jax.errors.SimplifiedTraceback: For simplicity, JAX has removed its internal frames from the traceback of the following exception. Set JAX_TRACEBACK_FILTERING=off to include these.

The above exception was the direct cause of the following exception:

Traceback (most recent call last):
  File "/home/gpuadmin/UM_CISC7404_Reinforcement_gym_game/parallel-sac.py", line 536, in <module>
    trained_state = train(train_state, config, env_reset, env_step, env_params, buffer)
  File "/home/gpuadmin/UM_CISC7404_Reinforcement_gym_game/parallel-sac.py", line 396, in train
    train_state, actor_loss = update_actor(train_state, batch, update_key)
  File "/home/gpuadmin/miniconda3/envs/jax_rl/lib/python3.10/site-packages/equinox/_jit.py", line 209, in __call__
    return _call(self, False, args, kwargs)
  File "/home/gpuadmin/miniconda3/envs/jax_rl/lib/python3.10/site-packages/equinox/_jit.py", line 263, in _call
    marker, _, _ = out = jit_wrapper._cached(
  File "/home/gpuadmin/UM_CISC7404_Reinforcement_gym_game/parallel-sac.py", line 319, in update_actor
    loss, grads = eqx.filter_value_and_grad(actor_loss_fn)(state.actor)
  File "/home/gpuadmin/UM_CISC7404_Reinforcement_gym_game/parallel-sac.py", line 312, in actor_loss_fn
    action, (probs, log_probs) = eqx.filter_vmap(actor)(obs, key)
ValueError: vmap got inconsistent sizes for array axes to be mapped:
  * one axis had size 256: axis 0 of argument _dynamic_args[0] of type float32[256,128,128,3];
  * one axis had size 2: axis 0 of argument _dynamic_args[1] of type uint32[2]
